<!-- Generated by SpecStory -->

# Django SECRET_KEY environment variable error (2025-08-28 00:50Z)

_**User**_

Qué está mal? Me sale error de django.core.exceptions.ImproperlyConfigured: Set the SECRET_KEY environment variable

---

_**Assistant**_

El error django.core.exceptions.ImproperlyConfigured: Set the SECRET_KEY environment variable indica que tu proyecto Django requiere que la variable de entorno SECRET_KEY esté definida, pero no lo está.

Esto suele ocurrir cuando en tu archivo `settings.py` tienes algo como:

```python
SECRET_KEY = os.environ.get("SECRET_KEY")
```

y la variable de entorno no está configurada.

Solución rápida:
1. Puedes definir la variable de entorno antes de ejecutar el proyecto, por ejemplo en PowerShell:
```powershell
$env:SECRET_KEY="tu_clave_secreta"
```
y luego ejecuta el comando de Django.

2. Alternativamente, puedes agregar un valor por defecto en `settings.py` para desarrollo:
```python
SECRET_KEY = os.environ.get("SECRET_KEY", "clave_insegura_para_desarrollo")
```
pero esto solo es recomendable para desarrollo, nunca para producción.

¿Quieres que agregue un valor por defecto en tu `settings.py` o prefieres definir la variable de entorno?

---

_**User**_

Traceback (most recent call last):
  File "C:\Users\Fabrizio Kawabata\Desktop\IS2-Proyecto-27-08\IS2-CasaDeCambios\app\manage.py", line 22, in <module>        
    main()
    ~~~~^^
  File "C:\Users\Fabrizio Kawabata\Desktop\IS2-Proyecto-27-08\IS2-CasaDeCambios\app\manage.py", line 18, in main
    execute_from_command_line(sys.argv)
    ~~~~~~~~~~~~~~~~~~~~~~~~~^^^^^^^^^^
  File "C:\Users\Fabrizio Kawabata\Desktop\IS2-Proyecto-27-08\IS2-CasaDeCambios\app\.venv\Lib\site-packages\django\core\management\__init__.py", line 442, in execute_from_command_line
    utility.execute()
    ~~~~~~~~~~~~~~~^^
  File "C:\Users\Fabrizio Kawabata\Desktop\IS2-Proyecto-27-08\IS2-CasaDeCambios\app\.venv\Lib\site-packages\django\core\management\__init__.py", line 436, in execute
    self.fetch_command(subcommand).run_from_argv(self.argv)
    ~~~~~~~~~~~~~~~~~~^^^^^^^^^^^^
  File "C:\Users\Fabrizio Kawabata\Desktop\IS2-Proyecto-27-08\IS2-CasaDeCambios\app\.venv\Lib\site-packages\django\core\management\__init__.py", line 262, in fetch_command
    settings.INSTALLED_APPS
  File "C:\Users\Fabrizio Kawabata\Desktop\IS2-Proyecto-27-08\IS2-CasaDeCambios\app\.venv\Lib\site-packages\django\conf\__init__.py", line 81, in __getattr__
    self._setup(name)
    ~~~~~~~~~~~^^^^^^
  File "C:\Users\Fabrizio Kawabata\Desktop\IS2-Proyecto-27-08\IS2-CasaDeCambios\app\.venv\Lib\site-packages\django\conf\__init__.py", line 68, in _setup
    self._wrapped = Settings(settings_module)
                    ~~~~~~~~^^^^^^^^^^^^^^^^^
  File "C:\Users\Fabrizio Kawabata\Desktop\IS2-Proyecto-27-08\IS2-CasaDeCambios\app\.venv\Lib\site-packages\django\conf\__init__.py", line 166, in __init__
    mod = importlib.import_module(self.SETTINGS_MODULE)
  File "C:\Users\Fabrizio Kawabata\AppData\Local\Programs\Python\Python313\Lib\importlib\__init__.py", line 88, in import_module
    return _bootstrap._gcd_import(name[level:], package, level)
           ~~~~~~~~~~~~~~~~~~~~~~^^^^^^^^^^^^^^^^^^^^^^^^^^^^^^
  File "<frozen importlib._bootstrap>", line 1387, in _gcd_import
  File "<frozen importlib._bootstrap>", line 1360, in _find_and_load
  File "<frozen importlib._bootstrap>", line 1331, in _find_and_load_unlocked
  File "<frozen importlib._bootstrap>", line 935, in _load_unlocked
  File "<frozen importlib._bootstrap_external>", line 1026, in exec_module
  File "<frozen importlib._bootstrap>", line 488, in _call_with_frames_removed
  File "C:\Users\Fabrizio Kawabata\Desktop\IS2-Proyecto-27-08\IS2-CasaDeCambios\app\global_exchange_django\settings.py", line 27, in <module>
    SECRET_KEY = env.str("SECRET_KEY")  # Use env variable
  File "C:\Users\Fabrizio Kawabata\Desktop\IS2-Proyecto-27-08\IS2-CasaDeCambios\app\.venv\Lib\site-packages\environ\environ.py", line 221, in str
    value = self.get_value(var, cast=str, default=default)
  File "C:\Users\Fabrizio Kawabata\Desktop\IS2-Proyecto-27-08\IS2-CasaDeCambios\app\.venv\Lib\site-packages\environ\environ.py", line 413, in get_value
    raise ImproperlyConfigured(error_msg) from exc
django.core.exceptions.ImproperlyConfigured: Set the SECRET_KEY environment variable

---

_**Assistant**_

El error ocurre porque en tu archivo `settings.py` tienes esta línea:

```python
SECRET_KEY = env.str("SECRET_KEY")  # Use env variable
```

La librería `django-environ` exige que la variable de entorno `SECRET_KEY` esté definida, y si no lo está, lanza el error `ImproperlyConfigured`.

Soluciones posibles:

1. **Definir la variable de entorno**  
   En PowerShell, antes de ejecutar cualquier comando de Django, ejecuta:
   ```powershell
   $env:SECRET_KEY="una_clave_secreta_segura"
   ```
   Luego ejecuta tu comando Django normalmente.

2. **Agregar un valor por defecto en desarrollo**  
   Puedes modificar la línea en `settings.py` para que use un valor por defecto si la variable no está definida (solo recomendable para desarrollo):
   ```python
   SECRET_KEY = env.str("SECRET_KEY", default="clave_insegura_para_desarrollo")
   ```

¿Quieres que modifique tu `settings.py` para agregar el valor por defecto?

---

_**User**_

El directorio tiene algo que ver creo? Parece que no lee 

---

_**Assistant**_

Sí, la ubicación y configuración del archivo `.env` (o las variables de entorno) pueden afectar si Django puede leer la variable `SECRET_KEY`.

Con django-environ, normalmente debes tener un archivo `.env` en el mismo directorio que tu `settings.py` o donde inicializas `env = environ.Env()`.  
Ejemplo de `.env`:
```
SECRET_KEY=tu_clave_secreta
```

Verifica estos puntos:
1. ¿Existe un archivo `.env` en el directorio correcto (`` o ``)?
2. ¿En tu `settings.py` tienes algo como esto al inicio?
   ```python
   import environ
   env = environ.Env()
   environ.Env.read_env()  # Esto carga el .env
   ```
3. Si usas Docker, asegúrate de que el archivo `.env` esté copiado dentro del contenedor y que la ruta sea accesible.

¿Quieres que revise tu `settings.py` y te ayude a asegurar que el `.env` se lee correctamente?

---

_**User**_

Tengo un .env.dev en el proyecto

---

_**Assistant**_

Perfecto, tienes un archivo `.env.dev`.  
Por defecto, django-environ busca un archivo llamado `.env`. Si tu archivo se llama `.env.dev`, debes indicarle la ruta al cargar las variables.

En tu `settings.py`, asegúrate de tener esto al inicio:

```python
import environ
env = environ.Env()
environ.Env.read_env(env_file='.env.dev')
```

Esto hará que Django lea las variables desde `.env.dev`.

¿Quieres que lo agregue automáticamente en tu `settings.py`?

---

_**User**_

Dale

---

_**Assistant**_


```

```
Listo. Ahora tu archivo `settings.py` está configurado para leer las variables desde `.env.dev`.  
El único detalle es que el linter recomienda usar comillas dobles en vez de simples para el nombre del archivo. Si quieres, puedo corregirlo para que quede consistente con el estilo recomendado.

¿Quieres que lo cambie a comillas dobles?

---

_**User**_

Pero .env.dev está en carpeta padre del settings.py, tiene que ver algo? 

---

_**Assistant**_

Sí, la ubicación del archivo `.env.dev` importa.  
Por defecto, el método `env.read_env(env_file=".env.dev")` busca el archivo relativo al directorio donde se ejecuta el proceso, o puedes darle la ruta absoluta.

Si tu archivo `.env.dev` está en la carpeta `` y tu `settings.py` está en ``, debes indicarle la ruta correcta:

```python
from pathlib import Path
from environ import Env

BASE_DIR = Path(__file__).resolve().parent.parent
env = Env()
env.read_env(env_file=str(BASE_DIR / ".env.dev"))
```

¿Quieres que actualice tu `settings.py` para que lea el archivo `.env.dev` desde la carpeta padre correctamente?

---

_**User**_

O sea el .env.dev estaría en C:\Users\Fabrizio Kawabata\Desktop\IS2-Proyecto-27-08\IS2-CasaDeCambios\

El manage.py está en C:\Users\Fabrizio Kawabata\Desktop\IS2-Proyecto-27-08\IS2-CasaDeCambios\app

---

_**Assistant**_


```

```
Listo, ahora tu `settings.py` busca el archivo `.env.dev` en la raíz del proyecto, así que la variable `SECRET_KEY` y demás variables deberían leerse correctamente.

Sin embargo, hay varios errores de tipado en el uso de `env.str()` y `env.bool()` con el argumento `default`.  
La librería `django-environ` espera que uses `env("VAR", default=valor)` en vez de `env.str("VAR", default=valor)`.

¿Quieres que corrija estos errores para que tu configuración funcione correctamente?

---

_**User**_

psycopg.OperationalError: [Errno 11001] getaddrinfo failed
Traceback (most recent call last):
  File "C:\Users\Fabrizio Kawabata\Desktop\IS2-Proyecto-27-08\IS2-CasaDeCambios\app\manage.py", line 22, in <module>        
    main()
    ~~~~^^
  File "C:\Users\Fabrizio Kawabata\Desktop\IS2-Proyecto-27-08\IS2-CasaDeCambios\app\manage.py", line 18, in main
    execute_from_command_line(sys.argv)
    django.db.utils.OperationalError: [Errno 11001] getaddrinfo failed


---

_**Assistant**_

El error psycopg.OperationalError: [Errno 11001] getaddrinfo failed indica que Django no puede resolver el nombre del host de la base de datos configurado en tu archivo `.env.dev` o en `settings.py`.

Causas comunes:
- El valor de `SQL_HOST` (o `DB_HOST`) está mal escrito, vacío, o apunta a un host que no existe.
- Si usas Docker, el contenedor de la base de datos no está corriendo o el nombre del servicio no coincide.

Solución:
1. Verifica en tu `.env.dev` que la variable del host de la base de datos esté correctamente definida, por ejemplo:
   ```
   SQL_HOST=localhost
   ```
   o si usas Docker Compose, debe coincidir con el nombre del servicio de la base de datos, por ejemplo:
   ```
   SQL_HOST=db
   ```
2. Asegúrate de que el contenedor de la base de datos esté corriendo y accesible.

¿Quieres que revise tu configuración de base de datos en `settings.py` y te ayude a corregir el host?

---

_**User**_

si

---

_**Assistant**_

Tu configuración actual está usando:
```
SQL_HOST=db
```
Esto significa que Django intentará conectarse al host llamado `db`.  
Si estás usando Docker Compose, el nombre del servicio de la base de datos en tu archivo `docker-compose.dev.yml` debe ser `db` para que funcione correctamente.

Verifica:
- Si el servicio de la base de datos en tu `docker-compose.dev.yml` se llama `db`.
- Si no usas Docker, cambia `SQL_HOST=localhost` en tu `.env.dev`.

¿Quieres que te ayude a revisar el nombre del servicio en tu `docker-compose.dev.yml` o prefieres que cambie el host a `localhost` para pruebas locales?

---

_**User**_

mira

---

_**Assistant**_

Tu configuración de Docker Compose es correcta: el servicio de la base de datos se llama `db`, y el contenedor expone el puerto interno 5432 como 7432 en tu máquina.

Tu Django está configurado para conectarse a:
- host: `db`
- puerto: `5432`

Esto funcionará si ejecutas Django dentro del contenedor `web`, porque desde ahí el host `db` es accesible.

Si ejecutas Django localmente (fuera de Docker), debes cambiar el host a `localhost` y el puerto a `7432` en tu `.env.dev`:
```
SQL_HOST=localhost
SQL_PORT=7432
```

¿Quieres que actualice tu `.env.dev` para pruebas locales, o vas a trabajar siempre dentro de Docker?

---

_**User**_

C:\Users\Fabrizio Kawabata\Desktop\IS2-Proyecto-27-08\IS2-CasaDeCambios\app\.venv\Lib\site-packages\django\core\management\commands\makemigrations.py:161: RuntimeWarning: Got an error checking a consistent migration history performed for database connection 'default': [Errno 11001] getaddrinfo failed
  warnings.warn(

---

_**Assistant**_

Ese mensaje confirma que Django sigue sin poder resolver el host de la base de datos configurado en la variable `SQL_HOST`.

Solución:
- Si ejecutas Django dentro de Docker, deja `SQL_HOST=db` y `SQL_PORT=5432`.
- Si ejecutas Django localmente (fuera de Docker), cambia en tu `.env.dev`:
  ```
  SQL_HOST=localhost
  SQL_PORT=7432
  ```

Esto hará que Django intente conectarse al puerto 7432 de tu máquina local, que es el que expone el contenedor de la base de datos.

¿Quieres que actualice tu `.env.dev` para pruebas locales?

---

_**User**_

C:\Users\Fabrizio Kawabata\Desktop\IS2-Proyecto-27-08\IS2-CasaDeCambios\app\.venv\Lib\site-packages\django\core\management\commands\makemigrations.py:161: RuntimeWarning: Got an error checking a consistent migration history performed for database connection 'default': [Errno 11001] getaddrinfo failed
  warnings.warn(
No changes detected

---

_**Assistant**_

El mensaje "No changes detected" significa que no hay nuevas migraciones pendientes en tus modelos, lo cual es normal si no has hecho cambios recientes en ellos.

El warning de getaddrinfo failed sigue indicando que Django no puede conectarse a la base de datos, pero el comando `makemigrations` no necesita conectarse para funcionar, por eso no es un error fatal aquí.

Para solucionar el warning y poder ejecutar comandos que sí requieren conexión (como `migrate` o iniciar el servidor), asegúrate de que:
- Si ejecutas Django localmente, tu `.env.dev` tenga:
  ```
  SQL_HOST=localhost
  SQL_PORT=7432
  ```
- Si ejecutas Django dentro de Docker, mantén:
  ```
  SQL_HOST=db
  SQL_PORT=5432
  ```

¿Quieres que actualice tu `.env.dev` para el entorno local?

---

_**User**_

Que es ese warning

---

_**Assistant**_

Ese warning indica que Django intentó conectarse a la base de datos para verificar el historial de migraciones, pero no pudo resolver el nombre del host configurado (por ejemplo, `db` o `localhost`).  
El error específico `[Errno 11001] getaddrinfo failed` significa que el sistema operativo no pudo encontrar la dirección IP para el host especificado.

Esto ocurre cuando:
- El host de la base de datos en tu `.env.dev` no es accesible desde donde ejecutas el comando.
- El contenedor de la base de datos no está corriendo, o el nombre del host es incorrecto para el entorno actual.

No es un error fatal para `makemigrations`, pero sí lo será para comandos que requieren conexión real, como `migrate` o cuando inicies el servidor.

Solución:  
Asegúrate de que el host y puerto en tu `.env.dev` sean correctos para tu entorno (local o Docker), y que la base de datos esté corriendo y accesible.

---

_**User**_

puedes verificar?

---

_**Assistant**_

No pude acceder al último resultado del comando en tu terminal, pero puedo ayudarte a verificar la configuración.

Para que Django se conecte correctamente a la base de datos, revisa estos puntos en tu `.env.dev`:
- Si ejecutas Django dentro de Docker, usa:
  ```
  SQL_HOST=db
  SQL_PORT=5432
  ```
- Si ejecutas Django localmente (fuera de Docker), usa:
  ```
  SQL_HOST=localhost
  SQL_PORT=7432
  ```

Además, asegúrate de que el contenedor de la base de datos esté corriendo y accesible.

¿Quieres que actualice tu `.env.dev` para el entorno local, o prefieres mantener la configuración para Docker? Si tienes dudas sobre cómo lo estás ejecutando, dime y te ayudo a ajustar la configuración.

---

_**User**_

Esta bien poner esto?

---

_**Assistant**_

Sí, está bien poner esta línea en tu `settings.py`:

```python
AUTH_USER_MODEL = "usuarios.Usuario"
```

Esto le indica a Django que use el modelo personalizado `Usuario` definido en la app `usuarios` como el modelo de usuario principal del proyecto.  
Es la forma correcta de configurar un modelo de usuario personalizado.

Solo asegúrate de que:
- El modelo `Usuario` esté correctamente definido en `apps/usuarios/models.py`.
- La app `apps.usuarios` esté incluida en `INSTALLED_APPS` (ya lo está en tu configuración).

Si ya migraste la base de datos después de definir el modelo, no tendrás problemas. Si cambiaste el modelo de usuario después de migrar, podrías necesitar limpiar la base de datos y migraciones.

¿Necesitas verificar la definición del modelo `Usuario` o tienes otro detalle sobre esta configuración?

---

_**User**_

(app) PS C:\Users\Fabrizio Kawabata\Desktop\IS2-Proyecto-27-08\IS2-CasaDeCambios> docker compose -f docker-compose.dev.yml exec web uv run python manage.py flush
yesYou have requested a flush of the database.
This will IRREVERSIBLY DESTROY all data currently in the "postgres" database,
and return each table to an empty state.
Are you sure you want to do this?

    Type 'yes' to continue, or 'no' to cancel: yes
Flush cancelled.
(app) PS C:\Users\Fabrizio Kawabata\Desktop\IS2-Proyecto-27-08\IS2-CasaDeCambios> docker compose -f docker-compose.dev.yml exec web uv run python manage.py flush
You have requested a flush of the database.
This will IRREVERSIBLY DESTROY all data currently in the "postgres" database,
and return each table to an empty state.
Are you sure you want to do this?

    Type 'yes' to continue, or 'no' to cancel: yes
CommandError: Database postgres couldn't be flushed. Possible reasons:
  * The database isn't running or isn't configured correctly.
  * At least one of the expected database tables doesn't exist.
  * The SQL was invalid.
Hint: Look at the output of 'django-admin sqlflush'. That's the SQL this command wasn't able to run.
(app) PS C:\Users\Fabrizio Kawabata\Desktop\IS2-Proyecto-27-08\IS2-CasaDeCambios> docker compose -f docker-compose.dev.yml exec web uv run django-admin sqlflush 
Traceback (most recent call last):
  File "/app/.venv/bin/django-admin", line 10, in <module>
    sys.exit(execute_from_command_line())
             ~~~~~~~~~~~~~~~~~~~~~~~~~^^
  File "/app/.venv/lib/python3.13/site-packages/django/core/management/__init__.py", line 442, in execute_from_command_line 
    utility.execute()
    ~~~~~~~~~~~~~~~^^
  File "/app/.venv/lib/python3.13/site-packages/django/core/management/__init__.py", line 436, in execute
    self.fetch_command(subcommand).run_from_argv(self.argv)
    ~~~~~~~~~~~~~~~~~~~~~~~~~~~~~~~~~~~~~~~~~~~~^^^^^^^^^^^
  File "/app/.venv/lib/python3.13/site-packages/django/core/management/base.py", line 408, in run_from_argv
    parser = self.create_parser(argv[0], argv[1])
  File "/app/.venv/lib/python3.13/site-packages/django/core/management/base.py", line 371, in create_parser
    self.add_arguments(parser)
    ~~~~~~~~~~~~~~~~~~^^^^^^^^
  File "/app/.venv/lib/python3.13/site-packages/django/core/management/commands/sqlflush.py", line 19, in add_arguments     
    choices=tuple(connections),
            ~~~~~^^^^^^^^^^^^^
  File "/app/.venv/lib/python3.13/site-packages/django/utils/connection.py", line 73, in __iter__
    return iter(self.settings)
                ^^^^^^^^^^^^^
  File "/app/.venv/lib/python3.13/site-packages/django/utils/functional.py", line 47, in __get__
    res = instance.__dict__[self.name] = self.func(instance)
                                         ~~~~~~~~~^^^^^^^^^^
  File "/app/.venv/lib/python3.13/site-packages/django/utils/connection.py", line 45, in settings
    self._settings = self.configure_settings(self._settings)
                     ~~~~~~~~~~~~~~~~~~~~~~~^^^^^^^^^^^^^^^^
  File "/app/.venv/lib/python3.13/site-packages/django/db/utils.py", line 148, in configure_settings
    databases = super().configure_settings(databases)
  File "/app/.venv/lib/python3.13/site-packages/django/utils/connection.py", line 50, in configure_settings
    settings = getattr(django_settings, self.settings_name)
  File "/app/.venv/lib/python3.13/site-packages/django/conf/__init__.py", line 81, in __getattr__
    self._setup(name)
    ~~~~~~~~~~~^^^^^^
  File "/app/.venv/lib/python3.13/site-packages/django/conf/__init__.py", line 68, in _setup
    self._wrapped = Settings(settings_module)
                    ~~~~~~~~^^^^^^^^^^^^^^^^^
  File "/app/.venv/lib/python3.13/site-packages/django/conf/__init__.py", line 166, in __init__
    mod = importlib.import_module(self.SETTINGS_MODULE)
  File "/usr/local/lib/python3.13/importlib/__init__.py", line 88, in import_module
    return _bootstrap._gcd_import(name[level:], package, level)
           ~~~~~~~~~~~~~~~~~~~~~~^^^^^^^^^^^^^^^^^^^^^^^^^^^^^^
  File "<frozen importlib._bootstrap>", line 1387, in _gcd_import
  File "<frozen importlib._bootstrap>", line 1360, in _find_and_load
  File "<frozen importlib._bootstrap>", line 1310, in _find_and_load_unlocked
  File "<frozen importlib._bootstrap>", line 488, in _call_with_frames_removed
  File "<frozen importlib._bootstrap>", line 1387, in _gcd_import
  File "<frozen importlib._bootstrap>", line 1360, in _find_and_load
  File "<frozen importlib._bootstrap>", line 1324, in _find_and_load_unlocked
ModuleNotFoundError: No module named 'global_exchange_django'

---

_**Assistant**_

El error `ModuleNotFoundError: No module named 'global_exchange_django'` indica que Django no puede encontrar el módulo de configuración especificado en la variable `DJANGO_SETTINGS_MODULE` de tu `.env.dev`.

Esto suele pasar porque:
- El directorio de trabajo del contenedor no está correctamente configurado.
- El path del módulo no es accesible desde donde se ejecuta el comando.

En tu Docker Compose, el servicio `web` tiene:
```yaml
working_dir: /app
```
y tu estructura es:
- `settings.py`

La variable en tu `.env.dev` es:
```
DJANGO_SETTINGS_MODULE=global_exchange_django.settings
```

Solución:
1. Asegúrate de que el directorio `` contiene la carpeta `global_exchange_django` cuando el contenedor está corriendo.
2. Si el archivo `manage.py` está en ``, y la carpeta `global_exchange_django` también está en ``, la variable está correcta.
3. Si el error persiste, puede que el contenedor no esté montando correctamente el código fuente.

Verifica dentro del contenedor con:
```sh
docker compose -f docker-compose.dev.yml exec web ls /app
```
y asegúrate de que aparece `global_exchange_django`.

¿Quieres que te ayude a revisar el contenido del contenedor o ajustar la configuración de Docker Compose?

---

_**User**_

django.db.migrations.exceptions.MigrationSchemaMissing: Unable to create the django_migrations table (no schema has been selected to create in

---

_**Assistant**_

El error django.db.migrations.exceptions.MigrationSchemaMissing: Unable to create the django_migrations table (no schema has been selected to create in) ocurre porque en PostgreSQL necesitas especificar el esquema (schema) donde se crearán las tablas, y por defecto debe existir.

Esto suele pasar cuando:
- El usuario de la base de datos no tiene un esquema por defecto.
- El parámetro `SQL_DATABASE` en tu `.env.dev` no corresponde a un esquema válido, o el esquema no existe.

Solución rápida:
1. Verifica que en tu `.env.dev` tienes:
   ```
   SQL_DATABASE=postgres
   ```
   Esto debería funcionar si la base de datos `postgres` existe y el usuario tiene permisos.

2. Si usas un esquema distinto, asegúrate de que exista en la base de datos, o crea uno manualmente.

3. Si el problema persiste, puedes agregar la variable `OPTIONS` en tu configuración de base de datos en `settings.py` para especificar el esquema por defecto:
   ```python
   "OPTIONS": {
       "options": "-c search_path=public"
   }
   ```
   Esto fuerza a usar el esquema `public`, que es el estándar en PostgreSQL.

¿Quieres que agregue esta opción en tu configuración de base de datos?

---

_**User**_

auth.User.groups: (fields.E304) Reverse accessor 'Group.user_set' for 'auth.User.groups' clashes with reverse accessor for 'usuarios.Usuario.groups'.
        HINT: Add or change a related_name argument to the definition for 'auth.User.groups' or 'usuarios.Usuario.groups'.  
auth.User.user_permissions: (fields.E304) Reverse accessor 'Permission.user_set' for 'auth.User.user_permissions' clashes with reverse accessor for 'usuarios.Usuario.user_permissions'.
        HINT: Add or change a related_name argument to the definition for 'auth.User.user_permissions' or 'usuarios.Usuario.user_permissions'.
usuarios.Usuario.groups: (fields.E304) Reverse accessor 'Group.user_set' for 'usuarios.Usuario.groups' clashes with reverse accessor for 'auth.User.groups'.
        HINT: Add or change a related_name argument to the definition for 'usuarios.Usuario.groups' or 'auth.User.groups'.  
usuarios.Usuario.user_permissions: (fields.E304) Reverse accessor 'Permission.user_set' for 'usuarios.Usuario.user_permissions' clashes with reverse accessor for 'auth.User.user_permissions'.
        HINT: Add or change a related_name argument to the definition for 'usuarios.Usuario.user_permissions' or 'auth.User.user_permissions'.

---

_**Assistant**_

Este error ocurre porque tu modelo personalizado `Usuario` hereda de `AbstractUser` o `AbstractBaseUser` y no ha definido los argumentos `related_name` en los campos `groups` y `user_permissions`.  
Django intenta crear relaciones inversas con los mismos nombres que el modelo `auth.User`, lo que causa el conflicto.

Solución:
En tu modelo `Usuario` (en `apps/usuarios/models.py`), agrega los argumentos `related_name` únicos en los campos `groups` y `user_permissions`:

```python
from django.contrib.auth.models import AbstractUser, Group, Permission

class Usuario(AbstractUser):
    # ...otros campos...
    groups = models.ManyToManyField(
        Group,
        related_name="usuario_set",  # Cambia el nombre para evitar el conflicto
        blank=True,
        help_text="The groups this user belongs to.",
        verbose_name="groups",
    )
    user_permissions = models.ManyToManyField(
        Permission,
        related_name="usuario_set",  # Cambia el nombre para evitar el conflicto
        blank=True,
        help_text="Specific permissions for this user.",
        verbose_name="user permissions",
    )
    # ...otros métodos/campos...
```

Luego ejecuta `makemigrations` y `migrate`.

¿Quieres que realice este cambio automáticamente en tu modelo `Usuario`?

---

